Workbook

Sheet Calculator
A1: Residential CO2 Footprint Calculator
A2: Enter the blue cells (dropdowns). Lifecycle basis: combustion + upstream (well-to-tank). Results update in Excel / LibreOffice. Expanded from original (QC/ON/AB/BC + CO/MI/NY/WA) to ALL 13 Canadian provinces/territories and ALL 51 US states + DC. See cell D5 for valid jurisdiction codes.
A4: INPUTS
A5: Jurisdiction (province/state) | B5: NY | D5: AB AK AL AR AZ BC CA CO CT DC DE FL GA HI IA ID IL IN KS KY LA MA MB MD ME MI MN MO MS MT NB NC ND NE NH NJ NL NM NS NT NU NV NY OH OK ON OR PA PE QC RI SC SD SK TN TX UT VA VT WA WI WV WY YT (type any valid code in B5)
A6: Dwelling vintage | B6: 1960-1983 | D6: pre-1960 / 1960-1983 / 1984-1999 / 2000+
A7: Dwelling type | B7: attached | D7: detached / attached / apartment
A8: Floor area (heated) | B8: 1600 | D8: number
A9: Area units | B9: ft2 | D9: m2 or ft2
A10: Space heating system | B10: Electric heat pump | D10: ...or Don't know (country-average mix)
A11: Water heating system | B11: Electric | D11: ...or Don't know (country-average mix)
A12: Air conditioning? | B12: Yes | D12: Yes / No
A13: Household size (people) | B13: 3 | D13: 1 / 2 / 3 / 4 / 5 / 6+
A14: Windows/insulation significantly upgraded? | B14: No | D14: Yes / No / Unsure (Yes = -15% heating & cooling demand)
A15: INTERMEDIATE
A16: Floor area (m2) | B16: =IF($B$9="ft2",$B$8*0.092903,$B$8) -> 148.6448
A17: Vintage key | B17: =$B$5&"|"&$B$6 -> NY|1960-1983
A18: Dwelling key | B18: =$B$5&"|"&$B$7 -> NY|attached
A19: Grid factor (kg CO2e/GJ, delivered, lifecycle) | B19: =INDEX(P_EF_Elec!$F:$F,MATCH($B$5,P_EF_Elec!$A:$A,0)) -> 73.5611
A20: Envelope factor (type) | B20: =INDEX(P_BuildingType!$B:$B,MATCH($B$7,P_BuildingType!$A:$A,0)) -> 0.85
A21: Other-elec size factor | B21: =INDEX(P_Size!$B:$B,MATCH($B$13&"",P_Size!$A:$A,0)) -> 1.17
A22: Retrofit factor (windows/insulation) | B22: =IF($B$14="Yes",0.85,1) -> 1
A23: RESULTS (kg CO2e / year, lifecycle)
A24: End use | B24: kg CO2e/yr | D24: Energy (GJ/yr) and fuel
A25: Space heating | B25: =IF($B$10="Don't know",$I$25*INDEX(P_DKHeat!$K:$K,MATCH($B$5,P_DKHeat!$A:$A,0)),$G$25*$H$25) -> 1487.0886 | D25: =TEXT($G$25,"0.0")&" GJ "&$F$25 -> 20.2 GJ Electricity | E25: =IF($B$10="Don't know","mixed",IF($B$10="Natural gas",INDEX(P_GasEff!$B:$B,MATCH($B$5,P_GasEff!$A:$A,0)),IF($B$10="Electric heat pump",INDEX(P_HPcop!$B:$B,MATCH($B$5,P_HPcop!$A:$A,0)),INDEX(P_Systems!$C:$C,MATCH($B$10,P_Systems!$A:$A,0))))) -> 2 | F25: =IF($B$10="Don't know","mixed",INDEX(P_Systems!$B:$B,MATCH($B$10,P_Systems!$A:$A,0))) -> Electricity | G25: =IF($B$10="Don't know",$I$25*INDEX(P_DKHeat!$L:$L,MATCH($B$5,P_DKHeat!$A:$A,0)),$I$25/$E$25) -> 20.215693 | H25: =IF($B$10="Don't know",0,IF($F$25="Electricity",$B$19,INDEX(P_EF_Fuel!$D:$D,MATCH($F$25,P_EF_Fuel!$A:$A,0)))) -> 73.5611 | I25: =INDEX(P_Heating!$B:$B,MATCH($B$17,P_Heating!$A:$A,0))*$B$16*$B$20*$B$22 -> 40.431386
A26: Water heating | B26: =IF($B$11="Don't know",$I$26*INDEX(P_DKWater!$H:$H,MATCH($B$5,P_DKWater!$A:$A,0)),$G$26*$H$26) -> 890.90666 | D26: =TEXT($G$26,"0.0")&" GJ "&$F$26 -> 12.1 GJ Electricity | E26: =IF($B$11="Don't know","mixed",INDEX(P_WaterHeat!$C:$C,MATCH($B$11,P_WaterHeat!$A:$A,0))) -> 0.9 | F26: =IF($B$11="Don't know","mixed",INDEX(P_WaterHeat!$B:$B,MATCH($B$11,P_WaterHeat!$A:$A,0))) -> Electricity | G26: =IF($B$11="Don't know",$I$26*INDEX(P_DKWater!$I:$I,MATCH($B$5,P_DKWater!$A:$A,0)),$I$26/$E$26) -> 12.111111 | H26: =IF($B$11="Don't know",0,IF($F$26="Electricity",$B$19,INDEX(P_EF_Fuel!$D:$D,MATCH($F$26,P_EF_Fuel!$A:$A,0)))) -> 73.5611 | I26: =INDEX(P_U_water!$B:$B,MATCH($B$18,P_U_water!$A:$A,0)) -> 10.9
A27: Air conditioning | B27: =$G$27*$B$19 -> 557.65823 | D27: =TEXT($G$27,"0.0")&" GJ electricity" -> 7.6 GJ electricity | G27: =IF($B$12="Yes",INDEX(P_Cooling!$B:$B,MATCH($B$17,P_Cooling!$A:$A,0))*$B$16*$B$20*$B$22,0) -> 7.5808848
A28: Other electricity (appliances, lighting, plug) | B28: =$G$28*$B$19 -> 1377.0638 | D28: =TEXT($G$28,"0.0")&" GJ electricity" -> 18.7 GJ electricity | G28: =INDEX(P_OtherElec!$B:$B,MATCH($B$5,P_OtherElec!$A:$A,0))*$B$21 -> 18.72
A29: TOTAL (kg CO2e/yr) | B29: =SUM(B25:B28) -> 4312.7173
A30: TOTAL (tonnes CO2e/yr) | B30: =B29/1000 -> 4.3127173
A31: Intensity (kg CO2e/m2/yr) | B31: =$B$29/$B$16 -> 29.013577
A32: Intensity (kg CO2e/ft2/yr) | B32: =$B$29/($B$16/0.092903) -> 2.6954483

Sheet P_Heating
A1: key | B1: D_GJ_per_m2
A2: QC|pre-1960 | B2: 0.85
A3: QC|1960-1983 | B3: 0.65
A4: QC|1984-1999 | B4: 0.45
A5: QC|2000+ | B5: 0.34
A6: ON|pre-1960 | B6: 0.85
A7: ON|1960-1983 | B7: 0.55
A8: ON|1984-1999 | B8: 0.4
A9: ON|2000+ | B9: 0.33
A10: AB|pre-1960 | B10: 0.9
A11: AB|1960-1983 | B11: 0.65
A12: AB|1984-1999 | B12: 0.45
A13: AB|2000+ | B13: 0.36
... A257: DC|2000+ | B257: 0.196
A258: Space-heating useful heat demand D (GJ per m² per year). CA (QC/ON/AB/BC): NRCan CEUD Table 33 (2023); others estimated by HDD analogy. US: EIA RECS 2020 state×vintage, gas-consumed × 0.85 fleet AFUE; new states estimated by HDD interpolation (base 18°C).

Sheet P_Cooling
A1: key | B1: cool_GJ_per_m2
A2: QC|pre-1960 | B2: 0.053
A3: QC|1960-1983 | B3: 0.041
A4: QC|1984-1999 | B4: 0.029
A5: QC|2000+ | B5: 0.024
A6: ON|pre-1960 | B6: 0.043
A7: ON|1960-1983 | B7: 0.033
A8: ON|1984-1999 | B8: 0.023
A9: ON|2000+ | B9: 0.019
A10: AB|pre-1960 | B10: 0.009
A11: AB|1960-1983 | B11: 0.007
A12: AB|1984-1999 | B12: 0.005
A13: AB|2000+ | B13: 0.004
... A257: DC|2000+ | B257: 0.039
A258: Cooling electricity intensity (GJ per m² of heated area per year). CA (QC/ON/AB/BC): NRCan CEUD Table 4 (2018-2023 avg). US: RECS 2020 (CO/MI/NY/WA exact); others estimated by CDD^0.75 scaling from humid (NY) or dry (CO) reference, by vintage ratio.

Sheet P_BuildingType
A1: building_type | B1: envelope_factor
A2: detached | B2: 1
A3: attached | B3: 0.85
A4: apartment | B4: 0.7
A6: Applied to heating & cooling (envelope/area effect). Source: NRCan CEUD Table 33 building-type ratios.

Sheet P_Systems
A1: heating_system | B1: fuel | C1: efficiency_or_COP
A2: Natural gas | B2: Natural gas | C2: 0.85
A3: Heating oil / propane | B3: Oil/propane | C3: 0.84
A4: Electric baseboard | B4: Electricity | C4: 1
A5: Electric heat pump | B5: Electricity | C5: 1.9
A6: Wood | B6: Wood | C6: 0.65

Sheet P_WaterHeat
A1: water_heater | B1: fuel | C1: efficiency_or_COP
A2: Natural gas | B2: Natural gas | C2: 0.6
A3: Electric | B3: Electricity | C3: 0.9
A4: Heating oil / propane | B4: Oil/propane | C4: 0.59
A5: Heat-pump water heater | B5: Electricity | C5: 2.5

Sheet P_U_water
A1: key | B1: useful_hotwater_GJ_per_hh
A2: QC|detached | B2: 12.4
A3: QC|attached | B3: 11.3
A4: QC|apartment | B4: 8.5
A5: ON|detached | B5: 11.2
A6: ON|attached | B6: 10.2
A7: ON|apartment | B7: 7.6
A8: AB|detached | B8: 19.8
A9: AB|attached | B9: 18
A10: AB|apartment | B10: 13.5
A11: BC|detached | B11: 15.8
A12: BC|attached | B12: 14.4
A13: BC|apartment | B13: 10.8
... A193: DC|apartment | B193: 7.9
A194: Useful hot-water demand (GJ per household per year) by dwelling type. CA (QC/ON/AB/BC): NRCan CEUD Table 2 (2023). US: RECS 2020 (CO/MI/NY/WA exact); others scaled from RECS 2020 regional means by dwelling-type factors (detached 1.10, attached 1.00, apartment 0.75).

Sheet P_OtherElec
A1: jurisdiction | B1: other_elec_base_GJ_per_hh
A2: QC | B2: 20.2
A3: ON | B3: 12.8
A4: AB | B4: 16.2
A5: BC | B5: 17
A6: MB | B6: 16
A7: SK | B7: 15.5
A8: NS | B8: 18
A9: NB | B9: 17
A10: NL | B10: 20
A11: PE | B11: 16.5
A12: YT | B12: 20
A13: NT | B13: 21
... A65: DC | B65: 14.5
A66: Appliances/lighting/plug-load baseline (GJ per average household). CA (QC/ON/AB/BC): NRCan CEUD Table 2 (2023). US: RECS 2020 non-HVAC electricity (CO/MI/NY/WA exact); others from RECS 2020 state microdata or regional estimate.

Sheet P_Size
A1: household_size | B1: other_elec_factor | C1: water_factor_ref
A2: 1 | B2: 0.66 | C2: 0.64
A3: 2 | B3: 1 | C3: 0.95
A4: 3 | B4: 1.17 | C4: 1.21
A5: 4 | B5: 1.3 | C5: 1.4
A6: 5 | B6: 1.41 | C6: 1.52
A7: 6+ | B7: 1.51 | C7: 1.55
A9: Household-size load factors (normalized to mean=1), RECS 2020 (CO/MI/NY/WA pooled). other_elec_factor used; water_factor_ref optional.

Sheet P_EF_Fuel
A1: fuel | B1: combustion_kgCO2e_GJ | C1: upstream_kgCO2e_GJ | D1: lifecycle_kgCO2e_GJ
A2: Natural gas | B2: 50.3 | C2: 12.98 | D2: =B2+C2 -> 63.28
A3: Oil/propane | B3: 65.1 | C3: 14.7 | D3: =B3+C3 -> 79.8
A4: Wood | B4: 1.1 | C4: 0 | D4: =B4+C4 -> 1.1
A6: Combustion: EPA GHG Emission Factors Hub 2025 (CO2e, HHV; Oil/propane = mean of distillate 70.3 & propane 59.8). Upstream/well-to-tank: DOE BTO Best Practices Jan 2025 Table 2 / RESNET 301-2022 Add.B (NG +12.98; oil +13.89 & propane +15.54 -> mean +14.7). Wood biogenic-neutral; upstream excluded. lifecycle = combustion + upstream (USED in calc).

Sheet P_EF_Elec
A1: jurisdiction | B1: gCO2e_per_kWh | C1: grid_gross_loss | D1: combustion_kgCO2e_GJ_delivered | E1: upstream_kgCO2e_GJ | F1: lifecycle_kgCO2e_GJ_delivered
A2: QC | B2: 1.7 | C2: 0 | D2: =B2*0.277778/(1-C2) -> 0.4722226 | E2: 0.2 | F2: =D2+E2 -> 0.6722226
A3: ON | B3: 38 | C3: 0 | D3: =B3*0.277778/(1-C3) -> 10.555564 | E3: 3.4 | F3: =D3+E3 -> 13.955564
A4: AB | B4: 490 | C4: 0 | D4: =B4*0.277778/(1-C4) -> 136.11122 | E4: 22.7 | F4: =D4+E4 -> 158.81122
A5: BC | B5: 15 | C5: 0 | D5: =B5*0.277778/(1-C5) -> 4.16667 | E5: 1.3 | F5: =D5+E5 -> 5.46667
A6: MB | B6: 1.9 | C6: 0 | D6: =B6*0.277778/(1-C6) -> 0.5277782 | E6: 0.1 | F6: =D6+E6 -> 0.6277782
A7: SK | B7: 680 | C7: 0 | D7: =B7*0.277778/(1-C7) -> 188.88904 | E7: 18 | F7: =D7+E7 -> 206.88904
A8: NS | B8: 560 | C8: 0 | D8: =B8*0.277778/(1-C8) -> 155.55568 | E8: 23 | F8: =D8+E8 -> 178.55568
A9: NB | B9: 180 | C9: 0 | D9: =B9*0.277778/(1-C9) -> 50.00004 | E9: 13 | F9: =D9+E9 -> 63.00004
A10: NL | B10: 22 | C10: 0 | D10: =B10*0.277778/(1-C10) -> 6.111116 | E10: 1 | F10: =D10+E10 -> 7.111116
A11: PE | B11: 250 | C11: 0 | D11: =B11*0.277778/(1-C11) -> 69.4445 | E11: 18 | F11: =D11+E11 -> 87.4445
A12: YT | B12: 40 | C12: 0 | D12: =B12*0.277778/(1-C12) -> 11.11112 | E12: 3.5 | F12: =D12+E12 -> 14.61112
A13: NT | B13: 280 | C13: 0 | D13: =B13*0.277778/(1-C13) -> 77.77784 | E13: 28 | F13: =D13+E13 -> 105.77784
... A65: DC | B65: 272 | C65: 0.04 | D65: =B65*0.277778/(1-C65) -> 78.703767 | E65: 14 | F65: =D65+E65 -> 92.703767
A66: Combustion (D): CA = ECCC Emission Factors 2024, Table 5.2 consumption intensity (delivered basis, grid_loss=0); US = eGRID2023 state output rates grossed up for grid gross loss (subregion-level; CO/MI/NY/WA original, others eGRID2023 Rev 2). Upstream (E): Σ(generation share × heat rate × GREET/RESNET upstream factor) per delivered kWh (CER 2023 provincial mix; eGRID2023 state mix for US). lifecycle = combustion + upstream (USED in calc).

Sheet P_Vehicle
A1: P_Vehicle — Vehicle Lifecycle Emission Factors (kg CO₂e / km driven)
A2: Jurisdiction | B2: Grid Lifecycle (kgCO₂e/GJ) | C2: Gas Truck | D2: Gas Car | E2: Diesel Truck | F2: Diesel Car | G2: HEV Truck | H2: HEV Car | I2: PHEV* Truck | J2: PHEV* Car | K2: EV* Truck | L2: EV* Car | M2: Value Source | N2: Notes
A3: -> fuel type: | C3: Gasoline | E3: Diesel | G3: HEV (non-plug) | I3: PHEV* (grid-dep) | K3: BEV* (grid-dep)
A4: CANADA -- provinces and territories
A5: QC | B5: 0.7 | C5: 0.315 | D5: 0.215 | E5: 0.266 | F5: 0.181 | G5: 0.219 | H5: 0.144 | I5: 0.116 | J5: 0.081 | K5: 0.064 | L5: 0.04 | M5: Exact — Table 17 (original AFLEET study)
A6: ON | B6: 14 | C6: 0.315 | D6: 0.215 | E6: 0.266 | F6: 0.181 | G6: 0.219 | H6: 0.144 | I6: 0.117 | J6: 0.082 | K6: 0.067 | L6: 0.042 | M6: Exact — Table 17 (original AFLEET study)
A7: AB | B7: 158.8 | C7: 0.315 | D7: 0.215 | E7: 0.266 | F7: 0.181 | G7: 0.219 | H7: 0.144 | I7: 0.123 | J7: 0.086 | K7: 0.082 | L7: 0.051 | M7: Exact — Table 17 (original AFLEET study)
A8: BC | B8: 5.5 | C8: 0.315 | D8: 0.215 | E8: 0.266 | F8: 0.181 | G8: 0.219 | H8: 0.144 | I8: 0.116 | J8: 0.081 | K8: 0.064 | L8: 0.04 | M8: Exact — Table 17 (original AFLEET study)
A9: MB | B9: 0.6 | C9: 0.315 | D9: 0.215 | E9: 0.266 | F9: 0.181 | G9: 0.219 | H9: 0.144 | I9: 0.116 | J9: 0.081 | K9: 0.064 | L9: 0.04 | M9: Table 16 blend: 100% VT-surrogate
A10: SK | B10: 206.9 | C10: 0.315 | D10: 0.215 | E10: 0.266 | F10: 0.181 | G10: 0.219 | H10: 0.144 | I10: 0.123 | J10: 0.086 | K10: 0.081 | L10: 0.05 | M10: Table 16 blend: 100% CO (ceiling)
A11: NS | B11: 178.6 | C11: 0.315 | D11: 0.215 | E11: 0.266 | F11: 0.181 | G11: 0.219 | H11: 0.144 | I11: 0.123 | J11: 0.086 | K11: 0.081 | L11: 0.05 | M11: Table 16 blend: 100% CO (ceiling)
A12: NB | B12: 63 | C12: 0.315 | D12: 0.215 | E12: 0.266 | F12: 0.181 | G12: 0.219 | H12: 0.144 | I12: 0.119 | J12: 0.083 | K12: 0.07 | L12: 0.044 | M12: Table 16 blend: 36.8%WA+63.2%NY
A13: NL | B13: 7.1 | C13: 0.315 | D13: 0.215 | E13: 0.266 | F13: 0.181 | G13: 0.219 | H13: 0.144 | I13: 0.116 | J13: 0.081 | K13: 0.064 | L13: 0.04 | M13: Table 16 blend: 99.4%VT(VT)+0.6%WA
A14: PE | B14: 87.4 | C14: 0.315 | D14: 0.215 | E14: 0.266 | F14: 0.181 | G14: 0.219 | H14: 0.144 | I14: 0.122 | J14: 0.085 | K14: 0.078 | L14: 0.049 | M14: Table 16 blend: 76.2%NY+23.8%MI
A15: YT | B15: 14.6 | C15: 0.315 | D15: 0.215 | E15: 0.266 | F15: 0.181 | G15: 0.219 | H15: 0.144 | I15: 0.118 | J15: 0.082 | K15: 0.068 | L15: 0.042 | M15: Table 16 blend: 76.9%VT(VT)+23.1%WA
A16: NT | B16: 105.8 | C16: 0.315 | D16: 0.215 | E16: 0.266 | F16: 0.181 | G16: 0.219 | H16: 0.144 | I16: 0.131 | J16: 0.092 | K16: 0.102 | L16: 0.063 | M16: Table 16 blend: 37.3%NY+62.7%MI
A17: NU | B17: 250.7 | C17: 0.315 | D17: 0.215 | E17: 0.266 | F17: 0.181 | G17: 0.219 | H17: 0.144 | I17: 0.123 | J17: 0.086 | K17: 0.081 | L17: 0.05 | M17: Table 16 blend: 100% CO (ceiling)
A18: UNITED STATES -- all 50 states + DC
A19: CO | B19: 153.4 | C19: 0.315 | D19: 0.215 | E19: 0.266 | F19: 0.181 | G19: 0.219 | H19: 0.144 | I19: 0.123 | J19: 0.086 | K19: 0.081 | L19: 0.05 | M19: Exact — Table 17 (original AFLEET study)
A20: MI | B20: 119 | C20: 0.315 | D20: 0.215 | E20: 0.266 | F20: 0.181 | G20: 0.219 | H20: 0.144 | I20: 0.14 | J20: 0.098 | K20: 0.124 | L20: 0.077 | M20: Exact — Table 17 (original AFLEET study)
A21: NY | B21: 73.6 | C21: 0.315 | D21: 0.215 | E21: 0.266 | F21: 0.181 | G21: 0.219 | H21: 0.144 | I21: 0.116 | J21: 0.081 | K21: 0.064 | L21: 0.04 | M21: Exact — Table 17 (original AFLEET study)
A22: WA | B22: 40.3 | C22: 0.315 | D22: 0.215 | E22: 0.266 | F22: 0.181 | G22: 0.219 | H22: 0.144 | I22: 0.123 | J22: 0.086 | K22: 0.081 | L22: 0.05 | M22: Exact — Table 17 (original AFLEET study)
A23: AL | B23: 125.5 | C23: 0.315 | D23: 0.215 | E23: 0.266 | F23: 0.181 | G23: 0.219 | H23: 0.144 | I23: 0.133 | J23: 0.1 | K23: 0.134 | L23: 0.083 | M23: AFLEET_2024 — SERC region (elecSrc 8)
A24: AK | B24: 129 | C24: 0.315 | D24: 0.215 | E24: 0.266 | F24: 0.181 | G24: 0.219 | H24: 0.144 | I24: 0.138 | J24: 0.106 | K24: 0.152 | L24: 0.095 | M24: AFLEET_2024 — ASCC region (elecSrc 2)
A25: AZ | B25: 103.7 | C25: 0.315 | D25: 0.215 | E25: 0.266 | F25: 0.181 | G25: 0.219 | H25: 0.144 | I25: 0.119 | J25: 0.086 | K25: 0.081 | L25: 0.05 | M25: AFLEET_2024 — WECC region (elecSrc 11)
A26: AR | B26: 108.1 | C26: 0.315 | D26: 0.215 | E26: 0.266 | F26: 0.181 | G26: 0.219 | H26: 0.144 | I26: 0.133 | J26: 0.1 | K26: 0.134 | L26: 0.083 | M26: AFLEET_2024 — SERC region (elecSrc 8)
A27: CA | B27: 68 | C27: 0.315 | D27: 0.215 | E27: 0.266 | F27: 0.181 | G27: 0.219 | H27: 0.144 | I27: 0.119 | J27: 0.086 | K27: 0.081 | L27: 0.05 | M27: AFLEET_2024 — WECC region (elecSrc 11)
A28: CT | B28: 62.9 | C28: 0.315 | D28: 0.215 | E28: 0.266 | F28: 0.181 | G28: 0.219 | H28: 0.144 | I28: 0.114 | J28: 0.081 | K28: 0.064 | L28: 0.04 | M28: AFLEET_2024 — NPCC region (elecSrc 6)
A29: DE | B29: 92.7 | C29: 0.315 | D29: 0.215 | E29: 0.266 | F29: 0.181 | G29: 0.219 | H29: 0.144 | I29: 0.13 | J29: 0.098 | K29: 0.124 | L29: 0.077 | M29: AFLEET_2024 — RFC region (elecSrc 7)
A30: FL | B30: 116.6 | C30: 0.315 | D30: 0.215 | E30: 0.266 | F30: 0.181 | G30: 0.219 | H30: 0.144 | I30: 0.132 | J30: 0.099 | K30: 0.13 | L30: 0.081 | M30: AFLEET_2024 — FRCC region (elecSrc 3)
... A69: DC | B69: 92.7 | C69: 0.315 | D69: 0.215 | E69: 0.266 | F69: 0.181 | G69: 0.219 | H69: 0.144 | I69: 0.13 | J69: 0.098 | K69: 0.124 | L69: 0.077 | M69: AFLEET_2024 — RFC region (elecSrc 7)
A71: UNITS: kg CO2e / km driven, lifecycle (well-to-wheels + vehicle manufacturing).
A72: Gasoline / Diesel / HEV are grid-independent -- same for all jurisdictions.
A73: * PHEV and BEV values depend on local electricity grid mix.
A74: Color legend:
A75: GREEN = Exact Table 17 values from original study (8 jurisdictions: CO,MI,NY,WA,BC,AB,ON,QC).
A76: BLUE = AFLEET Online 2024 API values. Each US state maps to one of 10 NERC/eGRID regions.
A77: Unit conv: AFLEET metric tonnes CO2/yr / 21.97 = kg CO2e/km (Gasoline calibration).
A78: NERC map: ASCC=AK | FRCC=FL | HICC=HI | MRO=IA,MN,ND,NE,SD,WI
A79: NPCC=CT,ME,MA,NH,NY,RI,VT | RFC=DE,DC,IL,IN,MD,MI,NJ,OH,PA,VA,WV
...

Sheet P_GasEff
A1: jurisdiction | B1: gas_furnace_efficiency
A2: QC | B2: 0.88
A3: ON | B3: 0.89
A4: AB | B4: 0.87
A5: BC | B5: 0.87
A6: MB | B6: 0.88
A7: SK | B7: 0.87
A8: NS | B8: 0.86
A9: NB | B9: 0.86
A10: NL | B10: 0.86
A11: PE | B11: 0.86
A12: YT | B12: 0.87
A13: NT | B13: 0.87
... A65: DC | B65: 0.85
A66: CA (QC/ON/AB/BC): NRCan CEUD Table 21 stock split × Table 26 tier efficiencies (Medium 80%, High 90%); others use national CA average 0.87-0.88. US: ~0.85 national fleet AFUE (DOE/AHRI condensing share ~40-45%).

Sheet P_HPcop
A1: jurisdiction | B1: heatpump_seasonal_COP
A2: QC | B2: 1.9
A3: ON | B3: 1.9
A4: AB | B4: 1.9
A5: BC | B5: 1.9
A6: MB | B6: 1.9
A7: SK | B7: 1.9
A8: NS | B8: 1.9
A9: NB | B9: 1.9
A10: NL | B10: 1.9
A11: PE | B11: 1.9
A12: YT | B12: 1.9
A13: NT | B13: 1.9
... A65: DC | B65: 2
A66: CA: 1.9 (NRCan CEUD Table 26 national stock COP; conservative – includes electric-resistance backup on coldest days). US: 2.0 (federal-minimum HSPF era stock, NREL ResStock derated to real-world; consistent across all US states as state-specific stock data not available).

Sheet P_DKHeat
A1: jurisdiction | B1: country | C1: w_gas | D1: w_oilprop | E1: w_baseboard | F1: w_heatpump | G1: w_wood | H1: grid_kg_GJ_lifecycle | I1: gas_eff | J1: hp_cop | K1: DK_EFperEff | L1: DK_energy_per_demand
A2: QC | B2: CA | C2: 0.443 | D2: 0.059 | E2: 0.374 | F2: 0.079 | G2: 0.045 | H2: =INDEX(P_EF_Elec!$F:$F,MATCH(A2,P_EF_Elec!$A:$A,0)) -> 0.6722226 | I2: =INDEX(P_GasEff!$B:$B,MATCH(A2,P_GasEff!$A:$A,0)) -> 0.88 | J2: =INDEX(P_HPcop!$B:$B,MATCH(A2,P_HPcop!$A:$A,0)) -> 1.9 | K2: =C2*(63.28/I2)+D2*(79.8/0.84)+E2*H2+F2*(H2/J2)+G2*(1.1/0.65) -> 37.816243 | L2: =C2/I2+D2/0.84+E2+F2/J2+G2/0.65 -> 1.0584569
A3: ON | B3: CA | C3: 0.443 | D3: 0.059 | E3: 0.374 | F3: 0.079 | G3: 0.045 | H3: =INDEX(P_EF_Elec!$F:$F,MATCH(A3,P_EF_Elec!$A:$A,0)) -> 13.955564 | I3: =INDEX(P_GasEff!$B:$B,MATCH(A3,P_GasEff!$A:$A,0)) -> 0.89 | J3: =INDEX(P_HPcop!$B:$B,MATCH(A3,P_HPcop!$A:$A,0)) -> 1.9 | K3: =C3*(63.28/I3)+D3*(79.8/0.84)+E3*H3+F3*(H3/J3)+G3*(1.1/0.65) -> 42.97859 | L3: =C3/I3+D3/0.84+E3+F3/J3+G3/0.65 -> 1.0528006
A4: AB | B4: CA | C4: 0.443 | D4: 0.059 | E4: 0.374 | F4: 0.079 | G4: 0.045 | H4: =INDEX(P_EF_Elec!$F:$F,MATCH(A4,P_EF_Elec!$A:$A,0)) -> 158.81122 | I4: =INDEX(P_GasEff!$B:$B,MATCH(A4,P_GasEff!$A:$A,0)) -> 0.87 | J4: =INDEX(P_HPcop!$B:$B,MATCH(A4,P_HPcop!$A:$A,0)) -> 1.9 | K4: =C4*(63.28/I4)+D4*(79.8/0.84)+E4*H4+F4*(H4/J4)+G4*(1.1/0.65) -> 103.90164 | L4: =C4/I4+D4/0.84+E4+F4/J4+G4/0.65 -> 1.0642432
A5: BC | B5: CA | C5: 0.443 | D5: 0.059 | E5: 0.374 | F5: 0.079 | G5: 0.045 | H5: =INDEX(P_EF_Elec!$F:$F,MATCH(A5,P_EF_Elec!$A:$A,0)) -> 5.46667 | I5: =INDEX(P_GasEff!$B:$B,MATCH(A5,P_GasEff!$A:$A,0)) -> 0.87 | J5: =INDEX(P_HPcop!$B:$B,MATCH(A5,P_HPcop!$A:$A,0)) -> 1.9 | K5: =C5*(63.28/I5)+D5*(79.8/0.84)+E5*H5+F5*(H5/J5)+G5*(1.1/0.65) -> 40.174872 | L5: =C5/I5+D5/0.84+E5+F5/J5+G5/0.65 -> 1.0642432
A6: MB | B6: CA | C6: 0.443 | D6: 0.059 | E6: 0.374 | F6: 0.079 | G6: 0.045 | H6: =INDEX(P_EF_Elec!$F:$F,MATCH(A6,P_EF_Elec!$A:$A,0)) -> 0.6277782 | I6: =INDEX(P_GasEff!$B:$B,MATCH(A6,P_GasEff!$A:$A,0)) -> 0.88 | J6: =INDEX(P_HPcop!$B:$B,MATCH(A6,P_HPcop!$A:$A,0)) -> 1.9 | K6: =C6*(63.28/I6)+D6*(79.8/0.84)+E6*H6+F6*(H6/J6)+G6*(1.1/0.65) -> 37.797773 | L6: =C6/I6+D6/0.84+E6+F6/J6+G6/0.65 -> 1.0584569
A7: SK | B7: CA | C7: 0.443 | D7: 0.059 | E7: 0.374 | F7: 0.079 | G7: 0.045 | H7: =INDEX(P_EF_Elec!$F:$F,MATCH(A7,P_EF_Elec!$A:$A,0)) -> 206.88904 | I7: =INDEX(P_GasEff!$B:$B,MATCH(A7,P_GasEff!$A:$A,0)) -> 0.87 | J7: =INDEX(P_HPcop!$B:$B,MATCH(A7,P_HPcop!$A:$A,0)) -> 1.9 | K7: =C7*(63.28/I7)+D7*(79.8/0.84)+E7*H7+F7*(H7/J7)+G7*(1.1/0.65) -> 123.88177 | L7: =C7/I7+D7/0.84+E7+F7/J7+G7/0.65 -> 1.0642432
A8: NS | B8: CA | C8: 0.443 | D8: 0.059 | E8: 0.374 | F8: 0.079 | G8: 0.045 | H8: =INDEX(P_EF_Elec!$F:$F,MATCH(A8,P_EF_Elec!$A:$A,0)) -> 178.55568 | I8: =INDEX(P_GasEff!$B:$B,MATCH(A8,P_GasEff!$A:$A,0)) -> 0.86 | J8: =INDEX(P_HPcop!$B:$B,MATCH(A8,P_HPcop!$A:$A,0)) -> 1.9 | K8: =C8*(63.28/I8)+D8*(79.8/0.84)+E8*H8+F8*(H8/J8)+G8*(1.1/0.65) -> 112.48169 | L8: =C8/I8+D8/0.84+E8+F8/J8+G8/0.65 -> 1.0701641
A9: NB | B9: CA | C9: 0.443 | D9: 0.059 | E9: 0.374 | F9: 0.079 | G9: 0.045 | H9: =INDEX(P_EF_Elec!$F:$F,MATCH(A9,P_EF_Elec!$A:$A,0)) -> 63.00004 | I9: =INDEX(P_GasEff!$B:$B,MATCH(A9,P_GasEff!$A:$A,0)) -> 0.86 | J9: =INDEX(P_HPcop!$B:$B,MATCH(A9,P_HPcop!$A:$A,0)) -> 1.9 | K9: =C9*(63.28/I9)+D9*(79.8/0.84)+E9*H9+F9*(H9/J9)+G9*(1.1/0.65) -> 64.459202 | L9: =C9/I9+D9/0.84+E9+F9/J9+G9/0.65 -> 1.0701641
A10: NL | B10: CA | C10: 0.443 | D10: 0.059 | E10: 0.374 | F10: 0.079 | G10: 0.045 | H10: =INDEX(P_EF_Elec!$F:$F,MATCH(A10,P_EF_Elec!$A:$A,0)) -> 7.111116 | I10: =INDEX(P_GasEff!$B:$B,MATCH(A10,P_GasEff!$A:$A,0)) -> 0.86 | J10: =INDEX(P_HPcop!$B:$B,MATCH(A10,P_HPcop!$A:$A,0)) -> 1.9 | K10: =C10*(63.28/I10)+D10*(79.8/0.84)+E10*H10+F10*(H10/J10)+G10*(1.1/0.65) -> 41.232942 | L10: =C10/I10+D10/0.84+E10+F10/J10+G10/0.65 -> 1.0701641
A11: PE | B11: CA | C11: 0.443 | D11: 0.059 | E11: 0.374 | F11: 0.079 | G11: 0.045 | H11: =INDEX(P_EF_Elec!$F:$F,MATCH(A11,P_EF_Elec!$A:$A,0)) -> 87.4445 | I11: =INDEX(P_GasEff!$B:$B,MATCH(A11,P_GasEff!$A:$A,0)) -> 0.86 | J11: =INDEX(P_HPcop!$B:$B,MATCH(A11,P_HPcop!$A:$A,0)) -> 1.9 | K11: =C11*(63.28/I11)+D11*(79.8/0.84)+E11*H11+F11*(H11/J11)+G11*(1.1/0.65) -> 74.617805 | L11: =C11/I11+D11/0.84+E11+F11/J11+G11/0.65 -> 1.0701641
A12: YT | B12: CA | C12: 0.443 | D12: 0.059 | E12: 0.374 | F12: 0.079 | G12: 0.045 | H12: =INDEX(P_EF_Elec!$F:$F,MATCH(A12,P_EF_Elec!$A:$A,0)) -> 14.61112 | I12: =INDEX(P_GasEff!$B:$B,MATCH(A12,P_GasEff!$A:$A,0)) -> 0.87 | J12: =INDEX(P_HPcop!$B:$B,MATCH(A12,P_HPcop!$A:$A,0)) -> 1.9 | K12: =C12*(63.28/I12)+D12*(79.8/0.84)+E12*H12+F12*(H12/J12)+G12*(1.1/0.65) -> 43.975113 | L12: =C12/I12+D12/0.84+E12+F12/J12+G12/0.65 -> 1.0642432
A13: NT | B13: CA | C13: 0.443 | D13: 0.059 | E13: 0.374 | F13: 0.079 | G13: 0.045 | H13: =INDEX(P_EF_Elec!$F:$F,MATCH(A13,P_EF_Elec!$A:$A,0)) -> 105.77784 | I13: =INDEX(P_GasEff!$B:$B,MATCH(A13,P_GasEff!$A:$A,0)) -> 0.87 | J13: =INDEX(P_HPcop!$B:$B,MATCH(A13,P_HPcop!$A:$A,0)) -> 1.9 | K13: =C13*(63.28/I13)+D13*(79.8/0.84)+E13*H13+F13*(H13/J13)+G13*(1.1/0.65) -> 81.862082 | L13: =C13/I13+D13/0.84+E13+F13/J13+G13/0.65 -> 1.0642432
... A65: DC | B65: US | C65: 0.533 | D65: 0.086 | E65: 0.216 | F65: 0.146 | G65: 0.019 | H65: =INDEX(P_EF_Elec!$F:$F,MATCH(A65,P_EF_Elec!$A:$A,0)) -> 92.703767 | I65: =INDEX(P_GasEff!$B:$B,MATCH(A65,P_GasEff!$A:$A,0)) -> 0.85 | J65: =INDEX(P_HPcop!$B:$B,MATCH(A65,P_HPcop!$A:$A,0)) -> 2 | K65: =C65*(63.28/I65)+D65*(79.8/0.84)+E65*H65+F65*(H65/J65)+G65*(1.1/0.65) -> 74.673825 | L65: =C65/I65+D65/0.84+E65+F65/J65+G65/0.65 -> 1.0476705
A66: Used when space-heating = "Don't know". Lifecycle factors. CA weights: NRCan Tables 27 & 34 (2023). US weights: RECS 2020.

Sheet P_DKWater
A1: jurisdiction | B1: country | C1: w_gas | D1: w_electric | E1: w_oilprop | F1: w_hpwh | G1: grid_kg_GJ_lifecycle | H1: DK_EFperEff | I1: DK_energy_per_U
A2: QC | B2: CA | C2: 0.49 | D2: 0.492 | E2: 0.018 | F2: 0 | G2: =INDEX(P_EF_Elec!$F:$F,MATCH(A2,P_EF_Elec!$A:$A,0)) -> 0.6722226 | H2: =C2*(63.28/0.6)+D2*(G2/0.9)+E2*(79.8/0.59)+F2*(G2/2.5) -> 54.480725 | I2: =C2/0.6+D2/0.9+E2/0.59+F2/2.5 -> 1.3938418
A3: ON | B3: CA | C3: 0.49 | D3: 0.492 | E3: 0.018 | F3: 0 | G3: =INDEX(P_EF_Elec!$F:$F,MATCH(A3,P_EF_Elec!$A:$A,0)) -> 13.955564 | H3: =C3*(63.28/0.6)+D3*(G3/0.9)+E3*(79.8/0.59)+F3*(G3/2.5) -> 61.742285 | I3: =C3/0.6+D3/0.9+E3/0.59+F3/2.5 -> 1.3938418
A4: AB | B4: CA | C4: 0.49 | D4: 0.492 | E4: 0.018 | F4: 0 | G4: =INDEX(P_EF_Elec!$F:$F,MATCH(A4,P_EF_Elec!$A:$A,0)) -> 158.81122 | H4: =C4*(63.28/0.6)+D4*(G4/0.9)+E4*(79.8/0.59)+F4*(G4/2.5) -> 140.93004 | I4: =C4/0.6+D4/0.9+E4/0.59+F4/2.5 -> 1.3938418
A5: BC | B5: CA | C5: 0.49 | D5: 0.492 | E5: 0.018 | F5: 0 | G5: =INDEX(P_EF_Elec!$F:$F,MATCH(A5,P_EF_Elec!$A:$A,0)) -> 5.46667 | H5: =C5*(63.28/0.6)+D5*(G5/0.9)+E5*(79.8/0.59)+F5*(G5/2.5) -> 57.101689 | I5: =C5/0.6+D5/0.9+E5/0.59+F5/2.5 -> 1.3938418
A6: MB | B6: CA | C6: 0.49 | D6: 0.492 | E6: 0.018 | F6: 0 | G6: =INDEX(P_EF_Elec!$F:$F,MATCH(A6,P_EF_Elec!$A:$A,0)) -> 0.6277782 | H6: =C6*(63.28/0.6)+D6*(G6/0.9)+E6*(79.8/0.59)+F6*(G6/2.5) -> 54.456428 | I6: =C6/0.6+D6/0.9+E6/0.59+F6/2.5 -> 1.3938418
A7: SK | B7: CA | C7: 0.49 | D7: 0.492 | E7: 0.018 | F7: 0 | G7: =INDEX(P_EF_Elec!$F:$F,MATCH(A7,P_EF_Elec!$A:$A,0)) -> 206.88904 | H7: =C7*(63.28/0.6)+D7*(G7/0.9)+E7*(79.8/0.59)+F7*(G7/2.5) -> 167.21258 | I7: =C7/0.6+D7/0.9+E7/0.59+F7/2.5 -> 1.3938418
A8: NS | B8: CA | C8: 0.49 | D8: 0.492 | E8: 0.018 | F8: 0 | G8: =INDEX(P_EF_Elec!$F:$F,MATCH(A8,P_EF_Elec!$A:$A,0)) -> 178.55568 | H8: =C8*(63.28/0.6)+D8*(G8/0.9)+E8*(79.8/0.59)+F8*(G8/2.5) -> 151.72368 | I8: =C8/0.6+D8/0.9+E8/0.59+F8/2.5 -> 1.3938418
A9: NB | B9: CA | C9: 0.49 | D9: 0.492 | E9: 0.018 | F9: 0 | G9: =INDEX(P_EF_Elec!$F:$F,MATCH(A9,P_EF_Elec!$A:$A,0)) -> 63.00004 | H9: =C9*(63.28/0.6)+D9*(G9/0.9)+E9*(79.8/0.59)+F9*(G9/2.5) -> 88.553265 | I9: =C9/0.6+D9/0.9+E9/0.59+F9/2.5 -> 1.3938418
A10: NL | B10: CA | C10: 0.49 | D10: 0.492 | E10: 0.018 | F10: 0 | G10: =INDEX(P_EF_Elec!$F:$F,MATCH(A10,P_EF_Elec!$A:$A,0)) -> 7.111116 | H10: =C10*(63.28/0.6)+D10*(G10/0.9)+E10*(79.8/0.59)+F10*(G10/2.5) -> 58.000653 | I10: =C10/0.6+D10/0.9+E10/0.59+F10/2.5 -> 1.3938418
A11: PE | B11: CA | C11: 0.49 | D11: 0.492 | E11: 0.018 | F11: 0 | G11: =INDEX(P_EF_Elec!$F:$F,MATCH(A11,P_EF_Elec!$A:$A,0)) -> 87.4445 | H11: =C11*(63.28/0.6)+D11*(G11/0.9)+E11*(79.8/0.59)+F11*(G11/2.5) -> 101.91624 | I11: =C11/0.6+D11/0.9+E11/0.59+F11/2.5 -> 1.3938418
A12: YT | B12: CA | C12: 0.49 | D12: 0.492 | E12: 0.018 | F12: 0 | G12: =INDEX(P_EF_Elec!$F:$F,MATCH(A12,P_EF_Elec!$A:$A,0)) -> 14.61112 | H12: =C12*(63.28/0.6)+D12*(G12/0.9)+E12*(79.8/0.59)+F12*(G12/2.5) -> 62.100655 | I12: =C12/0.6+D12/0.9+E12/0.59+F12/2.5 -> 1.3938418
A13: NT | B13: CA | C13: 0.49 | D13: 0.492 | E13: 0.018 | F13: 0 | G13: =INDEX(P_EF_Elec!$F:$F,MATCH(A13,P_EF_Elec!$A:$A,0)) -> 105.77784 | H13: =C13*(63.28/0.6)+D13*(G13/0.9)+E13*(79.8/0.59)+F13*(G13/2.5) -> 111.93846 | I13: =C13/0.6+D13/0.9+E13/0.59+F13/2.5 -> 1.3938418
... A65: DC | B65: US | C65: 0.482 | D65: 0.463 | E65: 0.055 | F65: 0 | G65: =INDEX(P_EF_Elec!$F:$F,MATCH(A65,P_EF_Elec!$A:$A,0)) -> 92.703767 | H65: =C65*(63.28/0.6)+D65*(G65/0.9)+E65*(79.8/0.59)+F65*(G65/2.5) -> 105.96485 | I65: =C65/0.6+D65/0.9+E65/0.59+F65/2.5 -> 1.4109981
A66: Used when water-heating = "Don't know". Lifecycle factors. CA weights: NRCan Table 34 (2023). US weights: RECS 2020. HPWH ~0 (folded into electric).
